Workbook

Sheet balance sheet
A1: Line Item | B1: 2020 | C1: 2021 | D1: 2022 | E1: 2023 | F1: 2024 | G1: 2025 | H1: 2026 | I1: 2027 | J1: 2028 | K1: 2029
A2: ASSETS | H2: =H3-G3 -> 42767.764
A3: Property, plant and equipment | B3: 126479 | C3: 149102 | D3: 178983 | E3: 179649 | F3: 189456 | G3: =G63 -> 230007.57 | H3: =H63 -> 272775.34 | I3: =I63 -> 309623.69 | J3: =J63 -> 349543.21 | K3: =K63 -> 580483.55
A4: Exploration & evaluation assets | B4: 6768 | C4: 8648 | D4: 17579 | E4: 94272 | F4: 97326 | G4: =F4+G70 -> 103488.82 | H4: =G4+H70 -> 109870 | I4: =H4+I70 -> 115894.27 | J4: =I4+J70 -> 122520.21 | K4: =J4+K70 -> 150681.57
A5: Deferred tax asset | B5: 87 | C5: 194 | D5: 202 | E5: 153 | F5: 264 | G5: =F5 -> 264 | H5: =G5 -> 264 | I5: =H5 -> 264 | J5: =I5 -> 264 | K5: =J5 -> 264
A6: Total non-current assets | B6: 133334 | C6: 157944 | D6: 196764 | E6: 274074 | F6: =SUM(F3:F5) -> 287046 | G6: =SUM(G3:G5) -> 333760.4 | H6: =SUM(H3:H5) -> 382909.34 | I6: =SUM(I3:I5) -> 425781.96 | J6: =SUM(J3:J5) -> 472327.42 | K6: =SUM(K3:K5) -> 731429.12 | L6: =SUM(L3:L5) -> 0
A8: Inventories | B8: 16798 | C8: 20812 | D8: 18334 | E8: 20304 | F8: 23768 | G8: =-G78*'profit and loss'!G4/365 -> 27122.922 | H8: =-H78*'profit and loss'!H4/365 -> 18390.135 | I8: =-I78*'profit and loss'!I4/365 -> 19107.423 | J8: =-J78*'profit and loss'!J4/365 -> 19655.762 | K8: =-K78*'profit and loss'!K4/365 -> 82889.376
A9: Prepayments | B9: 1974 | C9: 6930 | D9: 3693 | E9: 2538 | F9: 6748 | G9: =G74*G82 -> 6892.7348 | H9: =H74*H82 -> 5544.4808 | I9: =I74*I82 -> 5610.432 | J9: =J74*J82 -> 5877.8259 | K9: =K74*K82 -> 24841.54
A10: Trade & other receivables | B10: 4962 | C10: 7938 | D10: 9185 | E10: 9952 | F10: 12675 | G10: =G79*G77/365 -> 16701.566 | H10: =H79*H77/365 -> 17293.304 | I10: =I79*I77/365 -> 16326.08 | J10: =J79*J77/365 -> 17956.631 | K10: =K79*K77/365 -> 76318.69
A11: Fixed term deposit | G11: 18500 | H11: 0 | I11: 0 | J11: 0 | K11: 0
A12: Income tax receivable | B12: 76 | C12: 101 | D12: 40 | E12: 1120 | F12: 355 | G12: =F12 -> 355 | H12: =G12 -> 355 | I12: =H12 -> 355 | J12: =I12 -> 355 | K12: =J12 -> 355
A13: Derivative financial assets | B13: 1184 | C13: 0 | D13: 440 | E13: 88 | F13: 0 | G13: 0 | H13: 0 | I13: 0 | J13: ='profit and loss'!J87 -> 3150000 | K13: =J13 -> 3150000
A14: Cash & cash equivalents | B14: 19092 | C14: 17152 | D14: 6735 | E14: 6708 | F14: 4260 | G14: ='cashflow sheet'!G49+G44 -> 19732.244 | H14: ='cashflow sheet'!H49+H44 -> 57034.182 | I14: ='cashflow sheet'!I49+I44 -> 82629.086 | J14: ='cashflow sheet'!J49+J44 -> -3037967.1 | K14: ='cashflow sheet'!K49+K44 -> -2942151.7 | M14: ='cashflow sheet'!F49+'balance sheet'!G44 -> 4260
A15: Assets held for sale | B15: 500 | C15: 0 | D15: 0 | E15: 13519 | F15: 13512 | G15: =F15 -> 13512 | H15: =G15 -> 13512 | I15: =H15 -> 13512 | J15: =I15 -> 13512 | K15: =J15 -> 13512
A16: Total current assets | B16: 44586 | C16: 52933 | D16: 38427 | E16: 54229 | F16: 61318 | G16: =SUM(G8:G15) -> 102816.47 | H16: =SUM(H8:H15) -> 112129.1 | I16: =SUM(I8:I15) -> 137540.02 | J16: =SUM(J8:J15) -> 169390.1 | K16: =SUM(K8:K15) -> 405764.91
A18: Total assets | B18: 177920 | C18: 210877 | D18: 235191 | E18: 328303 | F18: =F16+F6 -> 348364 | G18: =G16+G6 -> 436576.87 | H18: =H16+H6 -> 495038.44 | I18: =I16+I6 -> 563321.98 | J18: =J16+J6 -> 641717.52 | K18: =K16+K6 -> 1137194
A20: EQUITY AND LIABILITIES
A21: Share capital | B21: 74696 | C21: 82667 | D21: 83471 | E21: 165068 | F21: 165408 | G21: =F21 -> 165408 | H21: =G21 -> 165408 | I21: =H21 -> 165408 | J21: =I21 -> 165408 | K21: =J21 -> 165408
A22: Reserves | B22: 138310 | C22: 137779 | D22: 137801 | E22: 137819 | F22: 138465 | G22: =F22 -> 138465 | H22: =G22 -> 138465 | I22: =H22 -> 138465 | J22: =I22 -> 138465 | K22: =J22 -> 138465
A23: Retained loss | B23: -71487 | C23: -59150 | D23: -50222 | E23: -97143 | F23: -89996 | G23: =F23+'profit and loss'!G29 -> -22586.283 | H23: =G23+'profit and loss'!H29 -> 50778.545 | I23: =H23+'profit and loss'!I29 -> 113494.49 | J23: =I23+'profit and loss'!J29 -> 185896.04 | K23: =J23+'profit and loss'!K29 -> 555753.22
A24: Equity attributable to shareholders | B24: 141519 | C24: 161296 | D24: 171050 | E24: 205744 | F24: =SUM(F21:F23) -> 213877 | G24: =SUM(G21:G23) -> 281286.72 | H24: =SUM(H21:H23) -> 354651.54 | I24: =SUM(I21:I23) -> 417367.49 | J24: =SUM(J21:J23) -> 489769.04 | K24: =SUM(K21:K23) -> 859626.22
A26: Non-controlling interests | B26: 16524 | C26: 19260 | D26: 22409 | E26: 18456 | F26: 20587 | G26: =F26+'profit and loss'!G30 -> 30838.247 | H26: =G26+'profit and loss'!H30 -> 41995.11 | I26: =H26+'profit and loss'!I30 -> 51532.558 | J26: =I26+'profit and loss'!J30 -> 62542.933 | K26: =J26+'profit and loss'!K30 -> 118788.49
A27: Total equity | B27: 158043 | C27: 180556 | D27: 193459 | E27: 224200 | F27: =SUM(F24:F26) -> 234464 | G27: =SUM(G24:G26) -> 312124.96 | H27: =SUM(H24:H26) -> 396646.66 | I27: =SUM(I24:I26) -> 468900.05 | J27: =SUM(J24:J26) -> 552311.98 | K27: =SUM(K24:K26) -> 978414.72
A29: Deferred tax liabilities | B29: 4234 | C29: 8034 | D29: 5123 | E29: 46123 | F29: 48418 | G29: =F29 -> 48418 | H29: =G29 -> 48418 | I29: =H29 -> 48418 | J29: =I29 -> 48418 | K29: =J29 -> 48418
A30: Provisions | B30: 3567 | C30: 3294 | D30: 2958 | E30: 10985 | F30: 9664 | G30: =F30 -> 9664 | H30: =G30 -> 9664 | I30: =H30 -> 9664 | J30: =I30 -> 9664 | K30: =J30 -> 9664
A31: Loans & borrowings LT | B31: 0 | C31: 0 | D31: 0 | E31: 0 | F31: 1500 | G31: =G95 -> 831.3 | H31: =H95 -> 681.3 | I31: =I95 -> 531.3 | J31: =J95 -> 381.3 | K31: =K95 -> 231.3
A32: Loan notes instruments LT | B32: 0 | C32: 0 | D32: 0 | E32: 6447 | F32: 8313 | G32: =G96 -> 7481.7 | H32: =H96 -> 6131.7 | I32: =I96 -> 4781.7 | J32: =J96 -> 3431.7 | K32: =K96 -> 2081.7
A33: Cash-settled SBP LT | B33: 1934 | C33: 974 | D33: 1029 | E33: 374 | F33: 411 | G33: =F33 -> 411 | H33: =G33 -> 411 | I33: =H33 -> 411 | J33: =I33 -> 411 | K33: =J33 -> 411
A34: Lease liabilities LT | B34: 178 | C34: 331 | D34: 181 | E34: 41 | F34: 199 | G34: =G132 -> 179.1 | H34: =H132 -> 161.19 | I34: =I132 -> 145.071 | J34: =J132 -> 130.5639 | K34: =K132 -> 117.50751
A35: Total non-current liabilities | B35: 9913 | C35: 12633 | D35: 9291 | E35: 63970 | F35: =SUM(F29:F34) -> 68505 | G35: =SUM(G29:G34) -> 66985.1 | H35: =SUM(H29:H34) -> 65467.19 | I35: =SUM(I29:I34) -> 63951.071 | J35: =SUM(J29:J34) -> 62436.564 | K35: =SUM(K29:K34) -> 60923.508
A37: Cash-settled SBP ST | B37: 336 | C37: 2053 | D37: 1188 | E37: 920 | F37: 634 | G37: =F37 -> 634 | H37: =G37 -> 634 | I37: =H37 -> 634 | J37: =I37 -> 634 | K37: =J37 -> 634
A38: Income tax payable | B38: 495 | C38: 1562 | D38: 1324 | E38: 10 | F38: 2958 | G38: =F38 -> 2958 | H38: =G38 -> 2958 | I38: =H38 -> 2958 | J38: =I38 -> 2958 | K38: =J38 -> 2958
A39: Lease liabilities ST | B39: 61 | C39: 134 | D39: 132 | E39: 167 | F39: 95 | G39: =G131-G132 -> 85.5 | H39: =H131-H132 -> 76.95 | I39: =I131-I132 -> 69.255 | J39: =J131-J132 -> 62.3295 | K39: =K131-K132 -> 56.09655
A40: Loans and borrowings | F40: 1174 | G40: =F40 -> 1174 | H40: =G40 -> 1174 | I40: =H40 -> 1174 | J40: =I40 -> 1174 | K40: =J40 -> 1174
A41: Loan notes payable | B41: 0 | C41: 0 | D41: 7104 | G41: 0 | H41: 0 | I41: 0 | J41: 0 | K41: 0
A42: loan notes instrument | E42: 665 | F42: 855 | G42: 9175 | H42: =G42-H117 -> 2175 | I42: =H42-I117 -> 175 | J42: =I42-J117 -> 0 | K42: =J42-K117 -> 0 | L42: =H42-G42 -> -7000 | M42: =I42-H42 -> -2000 | N42: =J42-I42 -> -175
A43: Trade & other payables | B43: 8664 | C43: 9957 | D43: 17454 | E43: 20503 | F43: 26647 | G43: =-G80*'profit and loss'!G4/365 -> 30408.301 | H43: =-H80*'profit and loss'!H4/365 -> 20617.718 | I43: =-I80*'profit and loss'!I4/365 -> 21421.891 | J43: =-J80*'profit and loss'!J4/365 -> 22036.65 | K43: =-K80*'profit and loss'!K4/365 -> 92929.704
A44: Overdraft | B44: 0 | C44: 887 | D44: 5239 | E44: 17740 | F44: 12928 | G44: =F44 -> 12928 | H44: =0.1*'cashflow sheet'!H49 -> 5184.9257 | I44: =0.05*'cashflow sheet'!I49 -> 3934.7184 | J44: 0 | K44: 0
A45: Liabilities assoc. with assets held for sale | B45: 0 | C45: 0 | D45: 0 | E45: 128 | F45: 104 | G45: =F45 -> 104 | H45: =G45 -> 104 | I45: =H45 -> 104 | J45: =I45 -> 104 | K45: =J45 -> 104
A46: Total current liabilities | B46: 9964 | C46: 17688 | D46: 32441 | E46: 40133 | F46: =SUM(F37:F45) -> 45395 | G46: =SUM(G37:G45) -> 57466.801 | H46: =SUM(H37:H45) -> 32924.594 | I46: =SUM(I37:I45) -> 30470.864 | J46: =SUM(J37:J45) -> 26968.979 | K46: =SUM(K37:K45) -> 97855.8
...

Sheet cashflow sheet
B1: 2020 | C1: 2021 | D1: 2022 | E1: 2023 | F1: 2024 | G1: 2025 | H1: 2026 | I1: 2027 | J1: 2028 | K1: 2029
A2: Operating profit | G2: ='profit and loss'!G16 -> 104540 | H2: ='profit and loss'!H16 -> 113537.86 | I2: ='profit and loss'!I16 -> 97030.698 | J2: ='profit and loss'!J16 -> 111759.64 | K2: ='profit and loss'!K16 -> 568531.9
A3: Cash-settled share-based expense (note 9.1)
A4: Share-based expense included in production costs (note 9)
A5: Cash portion of cash-settled share-based expense
A6: Equity-settled share-based expense (note 9.2)
A7: Depreciation (note 13) | G7: =-'profit and loss'!G5 -> 14837.5 | H7: =-'profit and loss'!H5 -> 14583.75 | I7: =-'profit and loss'!I5 -> 17295.462 | J7: =-'profit and loss'!J5 -> 19631.851 | K7: =-'profit and loss'!K5 -> 22162.969
A8: Fair value loss on derivative instruments | G8: 0 | H8: =-'profit and loss'!H14 -> 0 | I8: =-'profit and loss'!I14 -> 0 | J8: =-'profit and loss'!J14 -> 0 | K8: =-'profit and loss'!K14 -> 0
A9: Gain on disposal of property, plant and equipment
A10: Cash generated from operations before working capital changes
A11: Increase in inventories | G11: ='balance sheet'!F8-'balance sheet'!G8 -> -3354.9222 | H11: ='balance sheet'!G8-'balance sheet'!H8 -> 8732.7874 | I11: ='balance sheet'!H8-'balance sheet'!I8 -> -717.28816 | J11: ='balance sheet'!I8-'balance sheet'!J8 -> -548.33917 | K11: ='balance sheet'!J8-'balance sheet'!K8 -> -63233.614
A12: Increase in prepayments | G12: ='balance sheet'!F9-'balance sheet'!G9 -> -144.73476 | H12: ='balance sheet'!G9-'balance sheet'!H9 -> 1348.254 | I12: ='balance sheet'!H9-'balance sheet'!I9 -> -65.951202 | J12: ='balance sheet'!I9-'balance sheet'!J9 -> -267.39394 | K12: ='balance sheet'!J9-'balance sheet'!K9 -> -18963.714
A13: Decrease in trade and other receivables | G13: ='balance sheet'!F10-'balance sheet'!G10 -> -4026.5657 | H13: ='balance sheet'!G10-'balance sheet'!H10 -> -591.73789 | I13: ='balance sheet'!H10-'balance sheet'!I10 -> 967.22381 | J13: ='balance sheet'!I10-'balance sheet'!J10 -> -1630.5511 | K13: ='balance sheet'!J10-'balance sheet'!K10 -> -58362.059
A14: Increase/(decrease) in trade and other payables | G14: ='balance sheet'!G43-'balance sheet'!F43 -> 3761.3014 | H14: ='balance sheet'!H43-'balance sheet'!G43 -> -9790.5834 | I14: ='balance sheet'!I43-'balance sheet'!H43 -> 804.17274 | J14: ='balance sheet'!J43-'balance sheet'!I43 -> 614.75909 | K14: ='balance sheet'!K43-'balance sheet'!J43 -> 70893.054
A15: Cash inflow from operations | B15: 37967 | C15: 38703 | D15: 49657 | E15: 26398 | F15: 55438 | G15: =SUM(G2:G14) -> 115612.58 | H15: =SUM(H2:H14) -> 127820.33 | I15: =SUM(I2:I14) -> 115314.32 | J15: =SUM(J2:J14) -> 129559.97 | K15: =SUM(K2:K14) -> 521028.54
A17: Interest received | B17: 56 | C17: 14 | D17: 17 | E17: 39 | F17: 26 | G17: 0
A18: Finance costs paid | B18: -405 | C18: -388 | D18: -192 | E18: -2462 | F18: -2864 | G18: =-'profit and loss'!G70 -> -992.0475 | H18: =-'profit and loss'!H70 -> -842.2695 | I18: =-'profit and loss'!I70 -> -692.8443 | J18: =-'profit and loss'!J70 -> -543.73662 | K18: =-'profit and loss'!K70 -> -394.91471
A19: Tax paid | B19: -6656 | C19: -7426 | D19: -6866 | E19: -9206 | F19: -10645 | G19: ='profit and loss'!G23 -> -25886.988 | H19: ='profit and loss'!H23 -> -28173.897 | I19: ='profit and loss'!I23 -> -24084.463 | J19: ='profit and loss'!J23 -> -27803.977 | K19: ='profit and loss'!K23 -> -142034.25
A20: Net cash inflow from operating activities | B20: 30962 | C20: 30903 | D20: 42616 | E20: 14769 | F20: 41955 | G20: =SUM(G15:G19) -> 88733.543 | H20: =SUM(H15:H19) -> 98804.161 | I20: =SUM(I15:I19) -> 90537.01 | J20: =SUM(J15:J19) -> 101212.26 | K20: =SUM(K15:K19) -> 378599.38
A22: Acquisition of property, plant and equipment | B22: -25081 | C22: -32112 | D22: -41495 | E22: -28556 | F22: -27477 | G22: =-'balance sheet'!G61 -> -55389.074 | H22: =-'balance sheet'!H61 -> -57351.514 | I22: =-'balance sheet'!I61 -> -54143.812 | J22: =-'balance sheet'!J61 -> -59551.372 | K22: =-'balance sheet'!K61 -> -253103.31
A23: Acquisition of exploration and evaluation assets | B23: -2759 | C23: -5717 | D23: -2596 | E23: -1837 | F23: -3835 | G23: =-'balance sheet'!G70 -> -6162.825 | H23: =-'balance sheet'!H70 -> -6381.1744 | I23: =-'balance sheet'!I70 -> -6024.2719 | J23: =-'balance sheet'!J70 -> -6625.9401 | K23: =-'balance sheet'!K70 -> -28161.355
A24: Proceeds from sale of assets held for sale | B24: – | C24: 500 | F24: 0 | G24: =-'balance sheet'!G11 -> -18500 | H24: =-G24 -> 18500 | I24: 0 | J24: 0 | K24: 0
A25: Realisation (purchase) of Gold ETF | B25: -1058 | C25: 1066 | F25: 0 | G25: 0 | H25: 0 | I25: 0 | J25: 0 | K25: 0
A26: Proceeds from disposal of subsidiary | B26: 900 | C26: 340 | F26: 0 | G26: 0 | H26: 0 | I26: 0 | J26: 0 | K26: 0
A27: Proceeds from derivative financial instruments | D27: – | E27: 178 | F27: 0 | G27: 0 | H27: 0 | I27: 0 | J27: =-'balance sheet'!J13 -> -3150000 | K27: 0
A28: Acquisition of Put options | D28: -478 | E28: -946 | F28: -743 | G28: 0 | H28: 0 | I28: 0 | J28: 0 | K28: 0
A29: Proceeds from call options | D29: 416 | E29: – | F29: – | G29: 0 | H29: 0 | I29: 0 | J29: 0 | K29: 0
A30: Acquisition of call options | D30: -176 | E30: – | F30: – | G30: 0 | H30: 0 | I30: 0 | J30: 0 | K30: 0
A31: Net cash used in investing activities | B31: -27998 | C31: -35923 | D31: -44329 | E31: -31161 | F31: -32055 | G31: =SUM(G22:G30) -> -80051.899 | H31: =SUM(H22:H30) -> -45232.688 | I31: =SUM(I22:I30) -> -60168.084 | J31: =SUM(J22:J30) -> -3216177.3 | K31: =SUM(K22:K30) -> -281264.66
A33: Cash flows from financing activities Dividends paid | B33: -4542 | C33: -8069 | D33: -8906 | E33: -11099 | F33: -12302 | G33: =-'balance sheet'!G149 -> 0 | H33: =-'balance sheet'!H149 -> 0 | I33: =-'balance sheet'!I149 -> 0 | J33: =-'balance sheet'!J149 -> 0 | K33: =-'balance sheet'!K149 -> 0
A34: Payment of lease liabilities | B34: -118 | C34: -129 | D34: -150 | E34: -184 | F34: -182 | G34: =-'balance sheet'!G128 -> -29.4 | H34: =-'balance sheet'!H128 -> -26.46 | I34: =-'balance sheet'!I128 -> -23.814 | J34: =-'balance sheet'!J128 -> -21.4326 | K34: =-'balance sheet'!K128 -> -19.28934
A35: Shares issued – equity raise (net of transaction cost) | B35: 12538 | C35: 7806 | D35: – | E35: 15569 | F35: – | G35: 0 | H35: 0 | I35: 0 | J35: 0 | K35: 0
A36: Proceeds from loans and borrowings | B36: – | C36: – | D36: – | E36: – | F36: 3000 | G36: 0 | H36: 0 | I36: 0 | J36: 0 | K36: 0
A37: Repayments of loans and borrowings | B37: -574 | C37: -361 | D37: – | E37: – | F37: -326 | G37: ='balance sheet'!G92 -> -1500 | H37: ='balance sheet'!H92 -> -1500 | I37: ='balance sheet'!I92 -> -1500 | J37: ='balance sheet'!J92 -> -1500 | K37: ='balance sheet'!K92 -> -1500
A38: Loan notes - Motapa payment | D38: – | E38: -7250 | F38: – | G38: 0 | H38: 0 | I38: 0 | J38: 0 | K38: 0
A39: Loan notes - solar bond issue receipts (net of transaction cost) | D39: – | E39: 6895 | F39: 1970 | G39: 0 | H39: 0 | I39: 0 | J39: 0 | K39: 0
A40: Repayment of gold loan | D40: -3698 | E40: – | F40: – | G40: 0 | H40: 0 | I40: 0 | J40: 0 | K40: 0
A41: redemption of bond | B41: 30 | C41: 165 | D41: – | E41: – | F41: 37 | G41: 0 | H41: 0 | I41: 0 | J41: 0 | K41: 0
A42: fixed term deposit | G42: 0
B43: – | C43: 2752 | G43: =-'balance sheet'!G117 -> 8320 | H43: =-'balance sheet'!H117 -> -7000 | I43: =-'balance sheet'!I117 -> -2000 | J43: =-'balance sheet'!J117 -> -175 | K43: =-'balance sheet'!K117 -> 0
...

Sheet profit and loss
A1: Item | B1: 2020 | C1: 2021 | D1: 2022 | E1: 2023 | F1: 2024 | G1: 2025 | H1: 2026 | I1: 2027 | J1: 2028 | K1: 2029 | L1: 2030
A2: Revenue | B2: 100002 | C2: 121329 | D2: 142082 | E2: 146314 | F2: 183018 | G2: 241158.75 | H2: =H50 -> 249703.03 | I2: =I50 -> 235737 | J2: =J50 -> 259281 | K2: =K46*K48+K47*K48 -> 1101987.7 | L2: =L50 -> 0
A3: Royalty | B3: -5007 | C3: -6083 | D3: -7124 | E3: -7637 | F3: -9263 | G3: -12206.25 | H3: =-H50*H55 -> -24970.303 | I3: =-I50*I55 -> -23573.7 | J3: =-J50*J55 -> -25928.1 | K3: =-K55*K2 -> -110198.77
A4: Production costs | B4: -43711 | C4: -53126 | D4: -62998 | E4: -82709 | F4: -80744 | G4: -92141.25 | H4: =-H46*H53/1000 -> -62474.463 | I4: =-I46*I53/1000 -> -64911.215 | J4: =-J46*J53/1000 -> -66774.018 | K4: =-(K46*K53+K52*K47)/1000 -> -281589.52
A5: Depreciation | B5: -4628 | C5: -8046 | D5: -10141 | E5: -14486 | F5: -16021 | G5: -14837.5 | H5: ='balance sheet'!H62 -> -14583.75 | I5: ='balance sheet'!I62 -> -17295.462 | J5: ='balance sheet'!J62 -> -19631.851 | K5: ='balance sheet'!K62 -> -22162.969
A6: Gross profit | B6: 46656 | C6: 54074 | D6: 61819 | E6: 41482 | F6: 76990 | G6: =SUM(G2:G5) -> 121973.75 | H6: =SUM(H2:H5) -> 147674.51 | I6: =SUM(I2:I5) -> 129956.62 | J6: =SUM(J2:J5) -> 146947.03 | K6: =SUM(K2:K5) -> 688036.43
A8: Other income | B8: 4765 | C8: 46 | D8: 60 | E8: 263 | F8: 1090 | G8: 277.5
A9: Other expenses | B9: -5315 | C9: -7136 | D9: -11782 | E9: -4367 | F9: -6940 | G9: -3786.25 | H9: =AVERAGE(B9:F9) -> -7108 | I9: =H9 -> -7108 | J9: =I9 -> -7108 | K9: =J9 -> -7108
A10: Administrative expenses | B10: -7997 | C10: -9091 | D10: -11941 | E10: -17429 | F10: -15658 | G10: -16567.5 | H10: =-H2*H55 -> -24970.303 | I10: =-I2*I55 -> -23573.7 | J10: =-J2*J55 -> -25928.1 | K10: =-K2*K55 -> -110198.77
A11: Cash-settled share-based expense | B11: -1413 | C11: -477 | D11: -609 | E11: -463 | F11: -201 | G11: -558.75 | H11: =H57 -> -632.6 | I11: =I57 -> -632.6 | J11: =J57 -> -632.6 | K11: =K57 -> -632.6
A12: Equity-settled share-based expense | B12: 0 | C12: 0 | D12: -484 | E12: -640 | F12: -1054 | G12: -1797.5 | H12: =AVERAGE(F12:G12) -> -1425.75 | I12: =AVERAGE(G12:H12) -> -1611.625 | J12: =AVERAGE(H12:I12) -> -1518.6875 | K12: =AVERAGE(I12:J12) -> -1565.1562
A13: Net foreign exchange gain (loss) | B13: 4305 | C13: 1184 | D13: 4411 | E13: -6772 | F13: -9722 | G13: -3686.25 | H13: 0 | I13: 0 | J13: 0 | K13: 0
A14: Net derivative financial instrument expense | B14: -226 | C14: -240 | D14: -1198 | E14: 1119 | F14: -831 | G14: -1990
A15: Profit on sale of non-current assets held for sale | B15: 0 | C15: 0 | D15: 0 | E15: 0 | F15: 0 | G15: 10675
A16: Operating profit | B16: 40735 | C16: 38360 | D16: 40276 | E16: 10955 | F16: =SUM(F6:F15) -> 43674 | G16: =SUM(G6:G15) -> 104540 | H16: =SUM(H6:H15) -> 113537.86 | I16: =SUM(I6:I15) -> 97030.698 | J16: =SUM(J6:J15) -> 111759.64 | K16: =SUM(K6:K15) -> 568531.9
A18: Finance income | B18: 62 | C18: 14 | D18: 17 | E18: 39 | F18: 26
A19: Finance cost | B19: -367 | C19: -375 | D19: -657 | E19: -3024 | F19: -3157 | G19: =-G70 -> -992.0475 | H19: =-H70 -> -842.2695 | I19: =-I70 -> -692.8443 | J19: =-J70 -> -543.73662 | K19: =-K70 -> -394.91471
A20: Profit before tax | B20: 40430 | C20: 37799 | D20: 39636 | E20: 7970 | F20: 40543 | G20: =SUM(G16:G19) -> 103547.95 | H20: =SUM(H16:H19) -> 112695.59 | I20: =SUM(I16:I19) -> 96337.854 | J20: =SUM(J16:J19) -> 111215.91 | K20: =SUM(K16:K19) -> 568136.99
A21: EBITDA | B21: =B20+B5 -> 35802 | C21: =C20+C5 -> 29753 | D21: =D20+D5 -> 29495 | E21: =E20+E5 -> -6516 | F21: =F20+F5 -> 24522 | G21: =G20+G5 -> 88710.452 | H21: =H20+H5 -> 98111.838 | I21: =I20+I5 -> 79042.392 | ... K21: =K20+K5 -> 545974.02
A23: Tax expense | B23: -15173 | C23: -14857 | D23: -16770 | E23: -12810 | F23: -17489 | G23: =-G58*G20 -> -25886.988 | H23: =-H58*H20 -> -28173.897 | I23: =-I58*I20 -> -24084.463 | J23: =-J58*J20 -> -27803.977 | K23: =-K58*K20 -> -142034.25
A24: Profit for the year | B24: 22257 | C24: 23142 | D24: 22866 | E24: -4840 | F24: 23054 | G24: =G20+G23 -> 77660.964 | H24: =H20+H23 -> 84521.691 | I24: =I20+I23 -> 72253.39 | J24: =J20+J23 -> 83411.93 | K24: =K20+K23 -> 426102.74
A26: Exchange differences on translation of foreign operations | B26: -173 | C26: -531 | D26: -462 | E26: -622 | F26: -116 | G26: 0
A27: Total comprehensive income for the year | B27: 25084 | C27: 22611 | D27: 22404 | E27: -5462 | F27: 22938 | G27: =G24 -> 77660.964 | H27: =H24 -> 84521.691 | I27: =I24 -> 72253.39 | J27: =J24 -> 83411.93 | K27: =K24 -> 426102.74
A29: Owners of the Company | B29: 20780 | C29: 18405 | D29: 17903 | E29: -7862 | F29: 17899 | G29: =(1-0.132)*G27 -> 67409.717 | H29: =(1-0.132)*H27 -> 73364.828 | I29: =(1-0.132)*I27 -> 62715.943 | J29: =(1-0.132)*J27 -> 72401.556 | K29: =(1-0.132)*K27 -> 369857.18
A30: Non-controlling interests | B30: 4477 | C30: 4737 | D30: 4963 | E30: 3022 | F30: 5155 | G30: =G27-G29 -> 10251.247 | H30: =H27-H29 -> 11156.863 | I30: =I27-I29 -> 9537.4475 | J30: =J27-J29 -> 11010.375 | K30: =K27-K29 -> 56245.562
A31: Total comprehensive income for the year (final) | B31: 25084 | C31: 22611 | D31: 22938 | E31: -5462 | F31: 22938 | G31: =G27 -> 77660.964 | H31: =H24 -> 84521.691 | I31: =I24 -> 72253.39 | J31: =J24 -> 83411.93 | K31: =K24 -> 426102.74
A33: EBITDA MARGIN | B33: =B21/B2 -> 0.35801284 | C33: =C21/C2 -> 0.24522579 | D33: =D21/D2 -> 0.20759139 | E33: =E21/E2 -> -0.044534358 | F33: =F21/F2 -> 0.13398682 | G33: =G21/G2 -> 0.36785086 | H33: =H21/H2 -> 0.39291409 | I33: =I21/I2 -> 0.33529905 | ... K33: =K21/K2 -> 0.49544475
A35: GROSS PROFIT MARGIN | B35: =B6/B2 -> 0.46655067 | C35: =C6/C2 -> 0.44568075 | D35: =D6/D2 -> 0.43509382 | E35: =E6/E2 -> 0.28351354 | F35: =F6/F2 -> 0.42066901 | G35: =G6/G2 -> 0.50578198 | H35: =H6/H2 -> 0.59140056 | I35: =I6/I2 -> 0.55127801 | ... K35: =K6/K2 -> 0.62435945
A37: PROFIT BEFEFORE TAX MARGIN | B37: =B20/B2 -> 0.40429191 | C37: =C20/C2 -> 0.31154135 | D37: =D20/D2 -> 0.27896567 | E37: =E20/E2 -> 0.054471889 | F37: =F20/F2 -> 0.22152466 | G37: =G20/G2 -> 0.42937672 | H37: =H20/H2 -> 0.45131847 | I37: =I20/I2 -> 0.40866667 | ... K37: =K20/K2 -> 0.51555657
A39: PROFIT AFTER TAX MARGIN | B39: =B24/B2 -> 0.22256555 | C39: =C24/C2 -> 0.19073758 | D39: =D24/D2 -> 0.16093523 | E39: =E24/E2 -> -0.033079541 | F39: =F24/F2 -> 0.12596575 | G39: =G24/G2 -> 0.32203254 | H39: =H24/H2 -> 0.33848885 | I39: =I24/I2 -> 0.3065 | ... K39: =K24/K2 -> 0.38666742
A44: ASSUMPTIONS
A45: YEAR | B45: 2020 | C45: 2021 | D45: 2022 | E45: 2023 | F45: 2024 | G45: 2025 | H45: 2026 | I45: 2027 | J45: 2028 | K45: 2029
A46: GOLD PRODUCTON (oz) | B46: 57899 | C46: 67476 | D46: 80775 | E46: 75416 | F46: 76656 | H46: 69847 | I46: 69848 | J46: 69840 | K46: 69847 | L46: 69847
A47: bilboes forecasted production (oz) | K47: 200000
A48: GOLD PRICE (forecast) (000) | E48: 1.91 | F48: 2.347 | H48: 3.575 | I48: 3.375 | J48: =I48*1.1 -> 3.7125 | K48: =J48*1.1 -> 4.08375
A49: FIDELITY DISCOUNTED BUYING PRICE
A50: REVENUE (000) | H50: =H46*H48 -> 249703.03 | I50: =I46*I48 -> 235737 | J50: =J46*J48 -> 259281 | K50: =K46*K48 -> 285237.69
A51: bilboes small l scale revenue
A52: bilboes production cost (AISC) per ounce | K52: 1061
A53: production costs per once | B53: =-B4/B46*1000 -> 754.95259 | C53: =-C4/C46*1000 -> 787.33179 | D53: =-D4/D46*1000 -> 779.91953 | E53: =-E4/E46*1000 -> 1096.7036 | F53: =-F4/F46*1000 -> 1053.3292 | H53: =AVERAGE(B53:F53) -> 894.44734 | I53: =AVERAGE(C53:G53) -> 929.32102 | J53: =AVERAGE(D53:H53) -> 956.09991 | K53: =AVERAGE(E53:I53) -> 993.45028
...

Sheet WACC
A2: WACC | E2: 2025 | F2: 2026 | G2: 2027 | H2: 2028 | I2: 2029
A3: Equity | E3: ='balance sheet'!G27 -> 312124.96 | F3: ='balance sheet'!H27 -> 396646.66 | G3: ='balance sheet'!I27 -> 468900.05 | H3: ='balance sheet'!J27 -> 552311.98 | I3: ='balance sheet'!K27 -> 978414.72
A4: Debt | E4: ='balance sheet'!G47 -> 124451.9 | F4: ='balance sheet'!H47 -> 98391.784 | G4: ='balance sheet'!I47 -> 94421.935 | H4: ='balance sheet'!J47 -> 89405.543 | I4: ='balance sheet'!K47 -> 158779.31
A7: Cost of debt | E7: =-'profit and loss'!G19/E4 -> 0.0079713326 | F7: =-'profit and loss'!H19/F4 -> 0.0085603642 | G7: =-'profit and loss'!I19/G4 -> 0.0073377473 | H7: =-'profit and loss'!J19/H4 -> 0.006081688 | I7: =-'profit and loss'!K19/I4 -> 0.0024871925
A8: tax rate | E8: 0.25 | F8: 0.25 | G8: 0.25 | H8: 0.25 | I8: 0.25
A9: d/(D+E) | E9: =E4/SUM(E3:E4) -> 0.28506298 | F9: =F4/SUM(F3:F4) -> 0.19875585 | G9: =G4/SUM(G3:G4) -> 0.16761628 | H9: =H4/SUM(H3:H4) -> 0.13932227 | I9: =I4/SUM(I3:I4) -> 0.13962376
A10: after Tax Cost of Debt
A13: Risk free rate (10 yr | E13: 0.04157
A14: expected market return
A15: market risk premium
A16: levered beta

Sheet MULTIPLES VALUATION
C1: MARKET DATA | J1: financial data | O1: valuation
A2: company | B2: ticker | C2: share price | D2: shares outstanding | E2: equity value | F2: net debt | G2: enterprise value | I2: revenue | J2: EBITDA | K2: Net income | M2: EV/REVENUE | O2: EV/EBITDA | Q2: P/E
A3: Padenga (Dallaglio) | C3: 0.25 | D3: 542000000 | E3: 135000000 | F3: ~$40 M | G3: **$175 M** | I3: $228 M | J3: $88 M | K3: $56 M | M3: 0.8 | O3: 2 | Q3: 2.4
A4: Caledonia Mining | C4: 25 | D4: 19300000 | E4: 4830000000 | F4: ($35 M) | G4: $448 M** | I4: **$240 M | J4: $120 M** | K4: **$65 M | M4: 1.9 | O4: 3.7 | Q4: 7.4
A5: Pan African | C5: $1.01** | D5: 2030000000 | E5: 2050000000 | F5: $150 M | G5: $2.20 B | I5: $540 M | J5: $227 M | K5: $142 M | M5: 4.1 | O5: 9.7 | Q5: 14.4
A6: Kinross Gold | C6: 27.38 | D6: 1210000000 | E6: $33.1 B | F6: ($500 M) | G6: $32.6 B** | I6: **$4.50 B | J6: $2.70 B** | K6: **$1.00 B | M6: 7.2 | O6: 12.1 | Q6: 33.1
A7: Gold Fields | C7: $42.21** | D7: 895000000 | E7: **$37.8 B | F7: $1.50 B | G7: $39.3 B | I7: $5.20 B | J7: $2.70 B | K7: $1.29 B | M7: 7.6 | O7: 14.6 | Q7: 29.3

Sheet Table020 (Page 13)
A1: Column1 | B1: Column4
B2: 2025
A3: Cash inflow from operations | B3: 78659
A4: Interest received | B4: 218
A5: Finance costs paid | B5: -1976
A6: Tax paid | B6: -21939
A7: Net cash inflow from operating activities | B7: 54962
A8: Cash flows used in investing activities
A9: Acquisition of property, plant and equipment | B9: -24058
A10: Expenditure on exploration and evaluation assets | B10: -4542
A11: Proceeds from sale of non-current asset held for sale (net of selling costs) | B11: 21966
A12: Proceeds from the sale of property plant and equipment | B12: 17
A13: Acquisition of put options | B13: -1592
A14: Investment in fixed-term deposits | B14: -18500
A15: Net cash used in investing activities | B15: -26709
A16: Cash flows from financing activities
A17: Dividends paid | B17: -14707
A18: Payment of lease liabilities | B18: -218
A19: Proceeds from loans and borrowings | B19: 1259
A20: Repayments of loans and borrowings | B20: -1004
A21: Bonds - solar bond issue receipts (net of transaction cost) | B21: 2387
A22: Net cash used in financing activities | B22: -12283
A23: Net (decrease)/increase in cash and cash equivalents | B23: 15970
A24: Effect of exchange rate fluctuations on cash and cash equivalents | B24: -24
A25: Net cash and cash equivalents at the beginning of the period | B25: -8668
A26: Net cash and cash equivalents at the end of the period | B26: 7278

Sheet Sheet7
A2: prepayments | G2: prepayments
A3: Opening Balance | G3: Opening Balance
A4: addition to prepayments | G4: addition to prepayments
A6: Expense Recognised | G6: Expense Recognised | R6: Column1
A7: Closing Balance | F7: ='balance sheet'!F9 -> 6748

Sheet Table065 (Page 40)
A1: Column1 | B1: PUs | C1: PUs_1
A2: Risk free rate | B2: 0.0455 | C2: 0.0388
A3: Fair value (USD) | B3: 9.41 | C3: 12.2
A4: Share price (USD) | B4: 9.41 | C4: 12.2
A5: Column1 | B5: Column2 | C5: Column3 | D5: Column4 | E5: Column5
A6: Volatility | D6: 0.77 | E6: 0.90
A7: January exercise price – 2020 awards (USD) | D7: – | E7: 13.10
A8: January exercise price 2021 | B8: – | D8: 11.89 | E8: 13.10
A9: January exercise price2022 | B9: – | D9: 11.89 | E9: 13.10
A10: April exercise price –2023 | D10: 10.87 | E10: –

Sheet Table066 (Page 40)
A1: Column1 | B1: Column2 | C1: Column3 | D1: Column4 | E1: Column5
A2: Volatility | D2: 0.77 | E2: 0.90
A3: January exercise price – 2020 awards (USD) | D3: – | E3: 13.10
A4: January exercise price | B4: – | C4: 2021 awards (USD) | D4: 11.89 | E4: 13.10
A5: January exercise price | B5: – | C5: 2022 awards (USD) | D5: 11.89 | E5: 13.10
A6: April exercise price – | B6: 2023 awards (USD) | D6: 10.87 | E6: –

Sheet Table100 (Page 56)
A1: Column1 | B1: Column2 | C1: Column3
B2: 2024 | C2: 2023
A3: Less than one year | B3: 121 | C3: 175
A4: One to two years | B4: 82 | C4: 42
A5: Two to three years | B5: 73 | C5: –
A6: Three to four years | B6: 79 | C6: –
A7: Total lease payments | B7: 355 | C7: 217
A8: Finance cost | B8: -61 | C8: (9)
A9: Present value of lease liabilities | B9: 294 | C9: 208
A10: Inventories | B10: 2024 | C10: 2023
A11: Consumable stores^{*} | B11: 20712 | C11: 18,001
A12: Gold in progress and Ore Stockpile^{@} | B12: 3056 | C12: 2,303
B13: 23768 | C13: 20,304

Sheet Sheet1

Sheet Table070 (Page 42)
A1: Column1 | B1: Column2 | C1: Column3 | D1: Column4 | E1: Column5 | F1: Column6 | G1: Column7 | H1: Column8
A2: Grant date | E2: January 24, 2022 | F2: April 7, 2023 | G2: April 8, 2024 | H2: May 13, 2024
A3: Number of units | B3: – | C3: remaining at | E3: 113,693 | F3: 80,773 | G3: 125,433 | H3: 13,140
A4: reporting date
A5: Share price (USD) - grant date | E5: 11.50 | F5: 16.91 | G5: 10.91 | H5: 10.01
A6: Fair value (USD) - grant date | E6: 10.15 | F6: 15.33 | G6: 9.53 | H6: 10.02
A7: Performance | B7: multiplier | C7: percentage | D7: at | E7: 100 % | F7: 100 % | G7: 100 % | H7: 100 %
A8: grant date
A9: Performance | B9: multiplier | C9: percentage | D9: at | E9: 105 % | F9: 42 % | G9: 97 % | H9: 97 %

Sheet Sheet8

Sheet Sheet9

Sheet Table015 (Page 11)
A1: Column1 | B1: Column2 | C1: Column3 | D1: Column4 | E1: Column5
A2: Unaudited | B2: 2025 | C2: 2024 | D2: 2025 | E2: 2024
C3: Restated^{*} | E3: Restated^{*}
A4: Revenue | B4: 71,440 | C4: 46,868 | D4: 192927 | E4: 135,503
A5: Royalty | B5: (3,487) | C5: (2,422) | D5: -9765 | E5: (6,831)
A6: Production costs | B6: (27,136) | C6: (21,085) | D6: -73713 | E6: (60,505)
A7: Depreciation | B7: (3,969) | C7: (4,048) | D7: -11870 | E7: (12,106)
A8: Gross profit | B8: 36,848 | C8: 19,313 | D8: 97579 | E8: 56,061
A9: Net foreign exchange loss | B9: (671) | C9: (3,132) | D9: -2949 | E9: (10,196)
A10: Administrative expenses | B10: (4,293) | C10: (3,954) | D10: -13254 | E10: (10,229)
A11: Fair value loss on derivative financial instrument | B11: - | C11: (20) | D11: -1592 | E11: (496)
A12: Equity-settled share-based expense | B12: (365) | C12: (279) | D12: -447 | E12: (785)
A13: Cash-settled share-based expense | B13: (995) | C13: (422) | D13: -1438 | E13: (479)
A14: Other expenses | B14: (1,083) | C14: (2,814) | D14: -3029 | E14: (4,078)
A15: Other income | B15: 81 | C15: 16 | D15: 222 | E15: 365
... A22: Profit for the period | B22: 18,654 | C22: 3,284 | D22: 53412 | E22: 15,538

Sheet Table075 (Page 45)
A1: Column1 | B1: Column2 | C1: Column3 | D1: Column4 | E1: Column5 | F1: Column6 | G1: Column7 | H1: Column8
A2: Finance cost paid | F2: 2024 | G2: 2023 | H2: 2022
A3: Finance cost | F3: 3,157 | G3: 3,024 | H3: 657
A4: Non cash - loan note interest (note 31) | F4: (86) | G4: (363) | H4: (302)
A5: Non cash - Unwinding of rehabilitation provision (note 29) | F5: (197) | G5: (109) | H5: (132)
A6: Non cash - Trade payables | F6: – | G6: (68) | H6: –
A7: Non cash - Finance cost on leases (note 19) | F7: (10) | G7: (22) | H7: (31)
F8: 2,864 | G8: 2,462 | H8: 192
A9: 16 | B9: Tax expense
A10: Tax recognised in profit or loss | F10: 2024 | G10: 2023 | H10: 2022
A11: Current tax | F11: 15,310 | G11: 7,642 | H11: 9,932
A12: Income tax - current year | F12: 14,382 | G12: 4,821 | H12: 8,707
A13: Income tax - change in tax estimate | F13: – | G13: 1,944 | H13: (46)
A14: Withholding tax - current year | F14: 928 | G14: 867 | H14: 1,271
A15: Acquisition of Bilboes Gold tax liability | F15: – | G15: 10 | H15: –
A16: Deferred tax expense | F16: 2,179 | G16: 5,168 | H16: ^{*} 4,427
A17: Origination and reversal of temporary differences | F17: 2,179 | G17: 5,168 | H17: ^{*} 4,427
A18: Tax expense – | C18: recognised in profit or loss | F18: 17,489 | G18: 12,810 | H18: ^{*} 14,359
A19: Tax recognised in other comprehensive income Income tax - current year | F19: – | G19: – | H19: –
A20: Tax expense | F20: 17,489 | G20: 12,810 | H20: ^{*} 14,359
A21: ^{*} Restated, refer to note 41.
A22: Unrecognised deferred tax assets | F22: 2024 | G22: 2023 | H22: 2022
A23: Bilboes Holdings (Private) Limited | F23: 4,428 | G23: ^{*} 4,447 | H23: —
A24: Caledonia Holdings Zimbabwe (Private) Limited | D24: – | E24: mining | F24: 2,942 | G24: 2,942 | H24: —
A25: Caledonia Holdings Zimbabwe (Private) Limited - services | F25: 3,438 | G25: 1,805 | H25: 1,805
A26: Blanket Employee Trust Services (Private) Limited | F26: 330 | G26: 260 | H26: 227
A27: Caledonia Mining Services (Private) Limited | F27: — | G27: — | H27: 69
A28: Greenstone Management Services (Pty) Ltd (UK)^{@} | F28: 359 | G28: 144 | H28: 176
A29: Tax losses carried forward | F29: 11,497 | G29: 9,598 | H29: 2,277

Sheet Table067 (Page 32)
A1: Column1 | B1: Column2 | C1: Column3
B2: June 30, | C2: June 30,
B3: 2025 | C3: 2024
A4: Operating profit | B4: 54,111 | C4: 21,455
A5: Adjustments for:
A6: Unrealised foreign exchange losses / (gains) (note 7) | B6: 560 | C6: 272

Sheet Sheet3

Sheet Sheet6

Sheet Table018 (Page 12)
A1: Column1 | B1: Column2 | C1: Column3 | D1: Column4
A2: Exploration and evaluation assets | B2: 102,813 | C2: 97,326 | D2: 94,272
A3: Property, plant and equipment | B3: 202,046 | C3: 189,456 | D3: 179,649
A4: Deferred tax asset | B4: 303 | C4: 264 | D4: 153
A5: Total non-current assets | B5: 305,162 | C5: 287,046 | D5: 274,074
A6: Income tax receivable | B6: - | C6: 355 | D6: 1,120
A7: Inventories | B7: 28,684 | C7: 23,768 | D7: 20,304
A8: Derivative financial assets | B8: - | C8: - | D8: 88
A9: Trade and other receivables | B9: 11,094 | C9: 12,675 | D9: 9,952
A10: Prepayments | B10: 14,148 | C10: 6,748 | D10: 2,538
A11: Fixed term deposit | B11: 18,500 | C11: - | D11: -
A12: Cash and cash equivalents | B12: 15,670 | C12: 4,260 | D12: 6,708
... A15: Total assets | B15: 393,258 | C15: 348,364 | D15: 328,303
A16: Equity and liabilities
A17: Share capital | B17: 166,234 | C17: 165,408 | D17: 165,068
A18: Reserves | B18: 138,875 | C18: 138,465 | D18: 137,819
A19: Retained loss | B19: (53,581) | C19: (89,996) | D19: (97,143)
A20: Equity attributable to equity holders of the parent | B20: 251,528 | C20: 213,877 | D20: 205,744
A21: Non-controlling interests | B21: 24,943 | C21: 20,587 | D21: 18,456
A22: Total equity | B22: 276,471 | C22: 234,464 | D22: 224,200
A23: Liabilities
A24: Deferred tax liabilities | B24: 50,422 | C24: 48,418 | D24: 46,123
A25: Provisions | B25: 10,324 | C25: 9,664 | D25: 10,985
A26: Loans and borrowings | B26: 1,313 | C26: 1,500 | D26: -
A27: Loan note instruments | B27: 2,455 | C27: 8,313 | D27: 6,447
A28: Cash-settled share-based payment | B28: 1,821 | C28: 411 | D28: 374
A29: Lease liabilities | B29: 927 | C29: 199 | D29: 41
A30: Total non-current liabilities | B30: 67,262 | C30: 68,505 | D30: 63,970
A31: Cash-settled share-based payment | B31: 2,236 | C31: 634 | D31: 920
A32: Income tax payable | B32: 6,530 | C32: 2,958 | D32: 10
A33: Lease liabilities | B33: 259 | C33: 95 | D33: 167
A34: Loans and borrowings | B34: 1,281 | C34: 1,174 | D34: -
A35: Loan note instruments | B35: 9,175 | C35: 855 | D35: 665
... A41: Total equity and liabilities | B41: 393,258 | C41: 348,364 | D41: 328,303

Sheet Sheet5
A1: Property, plant and equipment | B1: 202,046
A2: Exploration and evaluation assets | B2: 102,813
A3: Deferred tax asset | B3: 303
A4: Total non-current assets | B4: 305612
A6: Inventories | B6: 28,684
A7: Prepayments | B7: 14,148
A8: Trade and other receivables | B8: 11,094
A9: Fixed term deposit | B9: 18500
A10: Income tax receivable
A11: Derivative financial assets | B11: -
A12: Cash and cash equivalents | B12: 15,670
A13: Assets held for sale | B13: -
A14: Total current assets | B14: 88,096
A16: Total assets | B16: 393,258
A18: Equity and liabilities
A19: Share capital | B19: 166,234
A20: Reserves | B20: 138,875
A21: Retained loss | B21: (53,581)
A22: Equity attributable to equity holders of the parent | B22: 251,528
A24: Non-controlling interests | B24: 24,943
A25: Total equity | B25: 276,471
A27: Deferred tax liabilities | B27: 50,422
A28: Provisions | B28: 10,324
A29: Loans and borrowings | B29: 1,313
A30: Loan note instruments | B30: 2,455
A31: Cash-settled share-based payment | B31: 1,821
A32: Lease liabilities | B32: 927
... A45: Total equity and liabilities | B45: 393,258

Sheet Sheet4
B2: Scenario | C2: Original Units | D2: Perf. Multiplier | E2: Adjusted Units | F2: Fair Value ($) | G2: Total Grant Cost ($) | H2: Annual Expense ($)
B3: Bear Case | C3: 20000 | D3: 0.42 | E3: 8400 | F3: $10.02 | G3: $84,168 | H3: $28,056
B4: Base Case | C4: 20000 | D4: 1 | E4: 20000 | F4: $10.02 | G4: $200,400 | H4: $66,800
B5: Bull Case | C5: 20000 | D5: 1.05 | E5: 21000 | F5: $10.02 | G5: $210,420 | H5: $70,140
